Workbook
Name Агенты: Каналы!$K$4:$K$5
Name ГК: ЛБ!$I$22
Name Групп.пенсия: ЛБ!$M$22
Name ДМС: ЛБ!$R$22
Name ДМС_СИВ: ЛБ!$S$22
Name Индив.пенсия: ЛБ!$N$22
Name ИСЖ_СИВ: ЛБ!$Q$22
Name ИСЖ_Уралсиб: ЛБ!$AB$22
Name КорпЖ: ЛБ!$T$22
Name КорпНС: ЛБ!$U$22
Name Корпораты: Каналы!$L$4
Name КСЖ: ЛБ!$V$22
Name КСЖ_СИВ: ЛБ!$W$22
Name КСЖ_Уралсиб: ЛБ!$AD$22:$AD$23
Name Мульти: Каналы!$M$4
Name НовыеТП: Табл.НовыеТП[]
Name Новый: ЛБ!$J$4:$J$7
Name НП: ЛБ!$J$22
Name НС: ЛБ!$X$22:$X$23
Name НС_СИВ: ЛБ!$Y$22
Name НСЖ: ЛБ!$O$22:$O$28
Name НСЖ_КБ: ЛБ!$L$22
Name НСЖ_новый: ЛБ!$K$22
Name НСЖ_СИВ: ЛБ!$P$22:$P$28
Name НСЖ_СИВ_ДМС: ЛБ!$Z$22:$Z$28
Name НСЖ_СИВ_НС: ЛБ!$AA$22:$AA$28
Name НСЖ_Уралсиб: ЛБ!$AC$22:$AC$24
Name Портфель: ЛБ!$H$4:$H$6
Name Прочее_Уралсиб: ЛБ!$AE$22
Name Регион: Регионы!$B$2:$B$91
Name Розница: Каналы!$I$4:$I$7
Name СКБСЖ: ЛБ!$K$4:$K$18
Name Уралсиб: ЛБ!$L$4:$L$7
Name Уралсиб_: Каналы!$J$4

Sheet Дюрация
X1: изначально = факту, но с возможностью корректировки
F2: куб | G2: куб | H2: куб | I2: куб | J2: куб | K2: куб | L2: расчет | M2: расчет | N2: расчет | O2: расчет | P2: расчет | Q2: расчет | R2: расчет | S2: расчет | T2: расчет | U2: расчет | V2: расчет | W2: расчет | X2: ввод | Y2: ввод | Z2: ввод | AA2: ввод | AB2: ввод | AC2: ввод
F3: Дюрация факт 2025 | R3: Дюрация план 2026
F4: Дюрация факт 2025 | L4: Дюрация факт 2025, структура,% | R4: Дюрация факт 2025 | X4: Дюрация факт 2025, структура,%
B5: Компания | C5: подканал | D5: ЛБ | E5: Продукт | F5: < 1 г | G5: 1-3 | H5: 3-5 | I5: 5-10 | J5: 10+ | K5: итого | L5: < 1 г | M5: 1-3 | N5: 3-5 | O5: 5-10 | P5: 10+ | Q5: итого | R5: < 1 г | S5: 1-3 | T5: 3-5 | U5: 5-10 | V5: 10+ | W5: итого | X5: < 1 г | Y5: 1-3 | Z5: 3-5 | AA5: 5-10 | AB5: 10+ | AC5: итого
B6: СКБСЖ | C6: WM | D6: НСЖ | E6: НП | F6: 100000 | G6: 150000 | H6: 230000 | I6: 450000 | J6: 562000 | K6: =SUM(F6:J6) -> 1492000 | L6: =F6/$K$6 -> 0.067024129 | M6: =G6/$K$6 -> 0.10053619 | N6: =H6/$K$6 -> 0.1541555 | O6: =I6/$K$6 -> 0.30160858 | P6: =J6/$K$6 -> 0.3766756 | Q6: =K6/$K$6 -> 1 | R6: =$W$6*X6 -> 100536.19 | S6: =$W$6*Y6 -> 150804.29 | T6: =$W$6*Z6 -> 231233.24 | U6: =$W$6*AA6 -> 452412.87 | V6: =$W$6*AB6 -> 565013.4 | W6: 1500000 | X6: 0.067024129 | Y6: 0.10053619 | Z6: 0.1541555 | AA6: 0.30160858 | AB6: 0.3766756 | AC6: =SUM(X6:AB6) -> 1
K7: =SUM(F7:J7) -> 0 | Q7: =SUM(L7:P7) -> 0 | W7: =SUM(R7:V7) -> 0 | AC7: =SUM(X7:AB7) -> 0
K8: =SUM(F8:J8) -> 0 | Q8: =SUM(L8:P8) -> 0 | W8: =SUM(R8:V8) -> 0 | AC8: =SUM(X8:AB8) -> 0
K9: =SUM(F9:J9) -> 0 | Q9: =SUM(L9:P9) -> 0 | W9: =SUM(R9:V9) -> 0 | AC9: =SUM(X9:AB9) -> 0
K10: =SUM(F10:J10) -> 0 | Q10: =SUM(L10:P10) -> 0 | W10: =SUM(R10:V10) -> 0 | AC10: =SUM(X10:AB10) -> 0
K11: =SUM(F11:J11) -> 0 | Q11: =SUM(L11:P11) -> 0 | W11: =SUM(R11:V11) -> 0 | AC11: =SUM(X11:AB11) -> 0
K12: =SUM(F12:J12) -> 0 | Q12: =SUM(L12:P12) -> 0 | W12: =SUM(R12:V12) -> 0 | AC12: =SUM(X12:AB12) -> 0
K13: =SUM(F13:J13) -> 0 | Q13: =SUM(L13:P13) -> 0 | W13: =SUM(R13:V13) -> 0 | AC13: =SUM(X13:AB13) -> 0
K14: =SUM(F14:J14) -> 0 | Q14: =SUM(L14:P14) -> 0 | W14: =SUM(R14:V14) -> 0 | AC14: =SUM(X14:AB14) -> 0
K15: =SUM(F15:J15) -> 0 | Q15: =SUM(L15:P15) -> 0 | W15: =SUM(R15:V15) -> 0 | AC15: =SUM(X15:AB15) -> 0
K16: =SUM(F16:J16) -> 0 | Q16: =SUM(L16:P16) -> 0 | W16: =SUM(R16:V16) -> 0 | AC16: =SUM(X16:AB16) -> 0
K17: =SUM(F17:J17) -> 0 | Q17: =SUM(L17:P17) -> 0 | W17: =SUM(R17:V17) -> 0 | AC17: =SUM(X17:AB17) -> 0
K18: =SUM(F18:J18) -> 0 | Q18: =SUM(L18:P18) -> 0 | W18: =SUM(R18:V18) -> 0 | AC18: =SUM(X18:AB18) -> 0
... K33: =SUM(F33:J33) -> 0 | Q33: =SUM(L33:P33) -> 0 | W33: =SUM(R33:V33) -> 0 | AC33: =SUM(X33:AB33) -> 0

Sheet ФОРМА СКБСЖ
B1: ПЛАН ПРОДАЖ НА 2026-2028 гг
B2: выбор из списка | C2: формула | D2: выбор из списка | E2: формула | F2: выбор из списка | G2: выбор из списка | H2: формула | I2: выбор из списка | J2: формула | K2: выбор из списка | L2: выбор из списка | M2: выбор из списка | N2: выбор из списка | O2: выгрузка | P2: выгрузка | Q2: выгрузка | R2: выгрузка | S2: выгрузка | T2: выгрузка | U2: выгрузка | V2: выгрузка | W2: выгрузка | X2: ввод | Y2: ввод | Z2: ввод | AA2: расчет | AB2: ввод | AC2: ввод | AD2: ввод | AE2: ввод | AF2: ввод | AG2: ввод | AH2: ввод | AI2: ввод | AJ2: ввод | AK2: ввод | AL2: ввод | AM2: ввод | AN2: расчет | AO2: ввод | AP2: ввод | AQ2: ввод | AR2: ввод | AS2: ввод | AT2: ввод | AU2: ввод | AV2: ввод | AX2: Справочно
N3: ПРОМЕЖУТОЧН.ИТОГ | O3: =SUBTOTAL(9,O6:O161) -> 3.5992846e+09 | P3: =SUBTOTAL(9,P6:P161) -> 4.9361912e+09 | Q3: =SUBTOTAL(9,Q6:Q161) -> 7.4710875e+09 | R3: =SUBTOTAL(9,R6:R161) -> 2.5382695e+09 | S3: =SUBTOTAL(9,S6:S161) -> 3.0460406e+09 | T3: =SUBTOTAL(9,T6:T161) -> 3.1034584e+09 | U3: =SUBTOTAL(9,U6:U161) -> 3.4191617e+09 | V3: =SUBTOTAL(9,V6:V161) -> 1.5918354e+09 | ... AP3: =SUBTOTAL(9,AP6:AP161) -> 0 | AX3: =SUBTOTAL(9,AX6:AX161) -> 1.7488223e+09 | AY3: =SUBTOTAL(9,AY6:AY161) -> 1.3782305e+09 | AZ3: =SUBTOTAL(9,AZ6:AZ161) -> 1.4515232e+09 | BA3: =SUBTOTAL(9,BA6:BA161) -> 1.2856077e+09 | BB3: =SUBTOTAL(9,BB6:BB161) -> 1.2535721e+09 | BC3: =SUBTOTAL(9,BC6:BC161) -> 1.5559406e+09
B4: 1 | C4: 2 | D4: 3 | E4: 4 | F4: 5 | G4: 6 | H4: 7 | I4: 8 | J4: 9 | K4: 10 | L4: 11 | M4: 12 | N4: 13 | O4: Премия факт 9 мес 2025 | X4: Премия прогноз 4 кв 2025 | AA4: Итого | AB4: Премия план 2026 | AO4: Премия план 2027-2028 | AQ4: %КВ | AU4: Дополнительные поля | AX4: Премия прогноз 4 кв 2025 (1 версия) | BA4: Дельта прогноз 4кв 2025 (было / стало)
A5: ключ | B5: Компания | C5: Канал | D5: Подканал | E5: Подканал (код) | F5: Регион | G5: Новые ТП | H5: L/NL | I5: Портфель | J5: Сегмент | K5: ЛБ | L5: Продукт | M5: Периодичность | N5: Новый бизнес/ Пролонгация | O5: 45658 | P5: 45689 | Q5: 45717 | R5: 45748 | S5: 45778 | T5: 45809 | U5: 45839 | V5: 45870 | W5: 45901 | X5: 45931 | Y5: 45962 | Z5: 45992 | AA5: 2025 | AB5: 46023 | AC5: 46054 | AD5: 46082 | AE5: 46113 | AF5: 46143 | AG5: 46174 | AH5: 46204 | AI5: 46235 | AJ5: 46266 | AK5: 46296 | AL5: 46327 | AM5: 46357 | AN5: 2026 | AO5: 2027 | AP5: 2028 | AQ5: %КВ 2025 | AR5: %КВ 2026 | AS5: %КВ 2027 | AT5: %КВ 2028 | AU5: Ответственный (ФИО) | AV5: Пояснения к плану | AW5: коммент к корректировке прогноза 4кв25 | AX5: 45931 | AY5: 45962 | AZ5: 45992 | BA5: 45931 | BB5: 45962 | BC5: 45992
A6: =CONCATENATE(B6,C6,D6,E6,F6,G6,H6,I6,J6,K6,L6,M6,N6) -> СКБСЖРозницаWMЛайфНовыйГКГибкий курсЕдиновременнаяНовый | B6: СКБСЖ | C6: =IFERROR(VLOOKUP(D6,Каналы!$B:$C,2,0),"") -> Розница | D6: WM | H6: Лайф | I6: Новый | K6: ГК | L6: Гибкий курс | M6: Единовременная | N6: Новый | O6: 2.6573514e+08 | P6: 208306422 | Q6: 2.1587187e+08 | R6: 408691916 | S6: 183113109 | T6: 2.7109713e+08 | U6: 272935614 | V6: 185626860 | W6: 2.6235146e+08 | X6: 270000000 | Y6: 220000000 | Z6: 220000000 | AA6: =SUM(O6:Z6) -> 2.9837295e+09 | AB6: 150000000 | AC6: 150000000 | AD6: 200000000 | AE6: 200000000 | AF6: 150000000 | AG6: 200000000 | AH6: 200000000 | AI6: 200000000 | AJ6: 300000000 | AK6: 350000000 | AL6: 350000000 | AM6: 350000000 | AN6: =SUM(AB6:AM6) -> 2800000000 | AW6: ок | AX6: 270000000 | AY6: 220000000 | AZ6: 220000000 | BA6: =X6-AX6 -> 0 | BB6: =Y6-AY6 -> 0 | BC6: =Z6-AZ6 -> 0
A7: =CONCATENATE(B7,C7,D7,E7,F7,G7,H7,I7,J7,K7,L7,M7,N7) -> СКБСЖРозницаWMЛайфНовыйНПНПЕдиновременнаяНовый | B7: СКБСЖ | C7: =IFERROR(VLOOKUP(D7,Каналы!$B:$C,2,0),"") -> Розница | D7: WM | H7: Лайф | I7: Новый | K7: НП | L7: НП | M7: Единовременная | N7: Новый | O7: 2.6297489e+09 | P7: 3941211255 | Q7: 6.3700647e+09 | R7: 1.0261065e+09 | S7: 1.9611793e+09 | T7: 1954316259 | U7: 2190823168 | V7: 328435677 | W7: 583395118 | X7: 1200000000 | Y7: 1200000000 | Z7: 1500000000 | AA7: =SUM(O7:Z7) -> 2.4885281e+10 | AB7: 200000000 | AC7: 350000000 | AD7: 350000000 | AE7: 350000000 | AF7: 300000000 | AG7: 350000000 | AH7: 500000000 | AI7: 600000000 | AJ7: 600000000 | AK7: 700000000 | AL7: 700000000 | AM7: 700000000 | AN7: =SUM(AB7:AM7) -> 5700000000 | AW7: увеличено (факт окт 1,2 млрд) | AX7: 393000000 | AY7: 350000000 | AZ7: 350000000 | BA7: =X7-AX7 -> 807000000 | BB7: =Y7-AY7 -> 850000000 | BC7: =Z7-AZ7 -> 1150000000
A8: =CONCATENATE(B8,C8,D8,E8,F8,G8,H8,I8,J8,K8,L8,M8,N8) -> СКБСЖРозницаWMЛайфНовыйНСЖ_КБНСЖ с КэшбекомРегулярнаяНовый | B8: СКБСЖ | C8: =IFERROR(VLOOKUP(D8,Каналы!$B:$C,2,0),"") -> Розница | D8: WM | H8: Лайф | I8: Новый | K8: НСЖ_КБ | L8: НСЖ с Кэшбеком | M8: Регулярная | N8: Новый | O8: -14180000 | P8: 5800000 | Q8: 8900000 | R8: -2130000 | S8: 3880000 | T8: 9560000 | U8: 12680000 | V8: -3880000 | W8: -2150000 | X8: 5500000 | Y8: 5500000 | Z8: 5500000 | AA8: =SUM(O8:Z8) -> 34980000 | AB8: 2000000 | AC8: 2500000 | AD8: 2500000 | AE8: 2500000 | AF8: 2500000 | AG8: 4000000 | AH8: 4000000 | AI8: 4000000 | AJ8: 5000000 | AK8: 5000000 | AL8: 5000000 | AM8: 5000000 | AN8: =SUM(AB8:AM8) -> 44000000 | AW8: ок | AX8: 5500000 | AY8: 5500000 | AZ8: 5500000 | BA8: =X8-AX8 -> 0 | BB8: =Y8-AY8 -> 0 | BC8: =Z8-AZ8 -> 0
A9: =CONCATENATE(B9,C9,D9,E9,F9,G9,H9,I9,J9,K9,L9,M9,N9) -> СКБСЖРозницаБанкострахованиеЛайфСКБЖИндив.пенсияИндив ПенсияРегулярнаяНовый | B9: СКБСЖ | C9: =IFERROR(VLOOKUP(D9,Каналы!$B:$C,2,0),"") -> Розница | D9: Банкострахование | H9: Лайф | I9: СКБЖ | K9: Индив.пенсия | L9: Индив Пенсия | M9: Регулярная | N9: Новый | V9: -0.01 | AA9: =SUM(O9:Z9) -> -0.01 | AN9: =SUM(AB9:AM9) -> 0 | AW9: 0 | BA9: =X9-AX9 -> 0 | BB9: =Y9-AY9 -> 0 | BC9: =Z9-AZ9 -> 0
A10: =CONCATENATE(B10,C10,D10,E10,F10,G10,H10,I10,J10,K10,L10,M10,N10) -> СКБСЖРозницаБанкострахованиеЛайфСКБЖИндив.пенсияИндив ПенсияРегулярнаяПролонгация | B10: СКБСЖ | C10: =IFERROR(VLOOKUP(D10,Каналы!$B:$C,2,0),"") -> Розница | D10: Банкострахование | H10: Лайф | I10: СКБЖ | K10: Индив.пенсия | L10: Индив Пенсия | M10: Регулярная | N10: Пролонгация | U10: 373954.08 | AA10: =SUM(O10:Z10) -> 373954.08 | AN10: =SUM(AB10:AM10) -> 0 | AW10: 0 | BA10: =X10-AX10 -> 0 | BB10: =Y10-AY10 -> 0 | BC10: =Z10-AZ10 -> 0
A11: =CONCATENATE(B11,C11,D11,E11,F11,G11,H11,I11,J11,K11,L11,M11,N11) -> СКБСЖРозницаБанкострахованиеЛайфСКБЖНСЖДело жизниЕдиновременнаяНовый | B11: СКБСЖ | C11: =IFERROR(VLOOKUP(D11,Каналы!$B:$C,2,0),"") -> Розница | D11: Банкострахование | H11: Лайф | I11: СКБЖ | K11: НСЖ | L11: Дело жизни | M11: Единовременная | N11: Новый | O11: 298190000 | P11: 304060000 | Q11: 400000000 | R11: 442256762 | S11: 344820997 | T11: 226560433 | U11: 205585836 | V11: 345433682 | W11: 322057921 | X11: 320000000 | Y11: 320000000 | Z11: 320000000 | AA11: =SUM(O11:Z11) -> 3848965631 | AB11: 200000000 | AC11: 250000000 | AD11: 250000000 | AE11: 300000000 | AF11: 200000000 | AG11: 300000000 | AH11: 300000000 | AI11: 300000000 | AJ11: 350000000 | AK11: 350000000 | AL11: 350000000 | AM11: 350000000 | AN11: =SUM(AB11:AM11) -> 3500000000 | AW11: подняли до уровня 3 кв | AX11: 167000000 | AY11: 167000000 | AZ11: 167000000 | BA11: =X11-AX11 -> 153000000 | BB11: =Y11-AY11 -> 153000000 | BC11: =Z11-AZ11 -> 153000000
A12: =CONCATENATE(B12,C12,D12,E12,F12,G12,H12,I12,J12,K12,L12,M12,N12) -> СКБСЖРозницаБанкострахованиеЛайфСКБЖНСЖДело жизниРегулярнаяПролонгация | B12: СКБСЖ | C12: =IFERROR(VLOOKUP(D12,Каналы!$B:$C,2,0),"") -> Розница | D12: Банкострахование | H12: Лайф | I12: СКБЖ | K12: НСЖ | L12: Дело жизни | M12: Регулярная | N12: Пролонгация | P12: 30000 | T12: 50000 | AA12: =SUM(O12:Z12) -> 80000 | AN12: =SUM(AB12:AM12) -> 0 | AW12: 0 | BA12: =X12-AX12 -> 0 | BB12: =Y12-AY12 -> 0 | BC12: =Z12-AZ12 -> 0
A13: =CONCATENATE(B13,C13,D13,E13,F13,G13,H13,I13,J13,K13,L13,M13,N13) -> СКБСЖРозницаБанкострахованиеЛайфСКБЖНСЖДетский капиталЕдиновременнаяНовый | B13: СКБСЖ | C13: =IFERROR(VLOOKUP(D13,Каналы!$B:$C,2,0),"") -> Розница | D13: Банкострахование | H13: Лайф | I13: СКБЖ | K13: НСЖ | L13: Детский капитал | M13: Единовременная | N13: Новый | R13: 19800000 | S13: 16540000 | T13: 9280000 | U13: 10340000 | V13: 11910000 | W13: 7279079 | X13: 10000000 | Y13: 10000000 | Z13: 10000000 | AA13: =SUM(O13:Z13) -> 105149079 | AB13: 10000000 | AC13: 10000000 | AD13: 10000000 | AE13: 10000000 | AF13: 10000000 | AG13: 10000000 | AH13: 12000000 | AI13: 12000000 | AJ13: 12000000 | AK13: 15000000 | AL13: 15000000 | AM13: 15000000 | AN13: =SUM(AB13:AM13) -> 141000000 | AW13: добавлено по факту 3 кв | BA13: =X13-AX13 -> 10000000 | BB13: =Y13-AY13 -> 10000000 | BC13: =Z13-AZ13 -> 10000000
A14: =CONCATENATE(B14,C14,D14,E14,F14,G14,H14,I14,J14,K14,L14,M14,N14) -> СКБСЖРозницаБанкострахованиеЛайфСКБЖНСЖМаксимальная выгодаРегулярнаяПролонгация | B14: СКБСЖ | C14: =IFERROR(VLOOKUP(D14,Каналы!$B:$C,2,0),"") -> Розница | D14: Банкострахование | H14: Лайф | I14: СКБЖ | K14: НСЖ | L14: Максимальная выгода | M14: Регулярная | N14: Пролонгация | O14: 19330000 | P14: 17660000 | Q14: 11250000 | R14: 5810000 | S14: 9710000 | T14: 23660000 | U14: 18560000 | V14: 12300000 | W14: 21420000 | X14: 17500000 | Y14: 17500000 | Z14: 18000000 | AA14: =SUM(O14:Z14) -> 192700000 | AN14: =SUM(AB14:AM14) -> 0 | AW14: подняли до уровня 3 кв | AX14: 3250000 | AY14: 3250000 | AZ14: 3250000 | BA14: =X14-AX14 -> 14250000 | BB14: =Y14-AY14 -> 14250000 | BC14: =Z14-AZ14 -> 14750000
A15: =CONCATENATE(B15,C15,D15,E15,F15,G15,H15,I15,J15,K15,L15,M15,N15) -> СКБСЖРозницаБанкострахованиеЛайфСКБЖНСЖПрочее (СКБЖ)ЕдиновременнаяНовый | B15: СКБСЖ | C15: =IFERROR(VLOOKUP(D15,Каналы!$B:$C,2,0),"") -> Розница | D15: Банкострахование | H15: Лайф | I15: СКБЖ | K15: НСЖ | L15: Прочее (СКБЖ) | M15: Единовременная | N15: Новый | O15: 9181746 | P15: 12461991 | Q15: 13482629 | R15: 2856378 | AA15: =SUM(O15:Z15) -> 37982744 | AN15: =SUM(AB15:AM15) -> 0 | AW15: 0 | BA15: =X15-AX15 -> 0 | BB15: =Y15-AY15 -> 0 | BC15: =Z15-AZ15 -> 0
A16: =CONCATENATE(B16,C16,D16,E16,F16,G16,H16,I16,J16,K16,L16,M16,N16) -> СКБСЖРозницаБанкострахованиеЛайфСКБЖНСЖПрочее (СКБЖ)РегулярнаяНовый | B16: СКБСЖ | C16: =IFERROR(VLOOKUP(D16,Каналы!$B:$C,2,0),"") -> Розница | D16: Банкострахование | H16: Лайф | I16: СКБЖ | K16: НСЖ | L16: Прочее (СКБЖ) | M16: Регулярная | N16: Новый | O16: 9126664.7 | P16: 5379997.2 | Q16: 6099997.8 | R16: 5220004.4 | S16: 4568462.5 | T16: 3797270 | U16: 3774374.8 | V16: 2502657.2 | W16: 1696500.9 | X16: 3800000 | Y16: 2500000 | Z16: 1700000 | AA16: =SUM(O16:Z16) -> 50165929 | AN16: =SUM(AB16:AM16) -> 0 | AW16: подняли до уровня 3 кв | BA16: =X16-AX16 -> 3800000 | BB16: =Y16-AY16 -> 2500000 | BC16: =Z16-AZ16 -> 1700000
A17: =CONCATENATE(B17,C17,D17,E17,F17,G17,H17,I17,J17,K17,L17,M17,N17) -> СКБСЖРозницаБанкострахованиеЛайфСКБЖНСЖПрочее (СКБЖ)РегулярнаяПролонгация | B17: СКБСЖ | C17: =IFERROR(VLOOKUP(D17,Каналы!$B:$C,2,0),"") -> Розница | D17: Банкострахование | H17: Лайф | I17: СКБЖ | K17: НСЖ | L17: Прочее (СКБЖ) | M17: Регулярная | N17: Пролонгация | O17: 4385385.4 | P17: 1848439.5 | Q17: 7086679.5 | R17: 2877013.2 | S17: 6254546.3 | T17: 5401937.5 | U17: 4377641.4 | V17: 4775136.2 | W17: 4447599 | X17: 4400000 | Y17: 4800000 | Z17: 4500000 | AA17: =SUM(O17:Z17) -> 55154378 | AN17: =SUM(AB17:AM17) -> 0 | AW17: подняли до уровня 3 кв | BA17: =X17-AX17 -> 4400000 | BB17: =Y17-AY17 -> 4800000 | BC17: =Z17-AZ17 -> 4500000
A18: =CONCATENATE(B18,C18,D18,E18,F18,G18,H18,I18,J18,K18,L18,M18,N18) -> СКБСЖРозницаБанкострахованиеНон-лайфСКБЖНСДело жизниЕдиновременнаяНовый | B18: СКБСЖ | C18: =IFERROR(VLOOKUP(D18,Каналы!$B:$C,2,0),"") -> Розница | D18: Банкострахование | H18: Нон-лайф | I18: СКБЖ | K18: НС | L18: Дело жизни | M18: Единовременная | N18: Новый | R18: 1273238 | S18: 1089003 | T18: 699567 | U18: 674164 | V18: 1126318 | W18: 1072079 | X18: 1049354.8 | Y18: 1043389.2 | Z18: 1065228.5 | AA18: =SUM(O18:Z18) -> 9092341.5 | AN18: =SUM(AB18:AM18) -> 0 | AW18: расчет | BA18: =X18-AX18 -> 1049354.8 | BB18: =Y18-AY18 -> 1043389.2 | BC18: =Z18-AZ18 -> 1065228.5
A19: =CONCATENATE(B19,C19,D19,E19,F19,G19,H19,I19,J19,K19,L19,M19,N19) -> СКБСЖРозницаБанкострахованиеНон-лайфСКБЖНСНСЕдиновременнаяНовый | B19: СКБСЖ | C19: =IFERROR(VLOOKUP(D19,Каналы!$B:$C,2,0),"") -> Розница | D19: Банкострахование | H19: Нон-лайф | I19: СКБЖ | K19: НС | L19: НС | M19: Единовременная | N19: Новый | O19: 48254 | P19: 58009 | Q19: 67371 | R19: 13622 | AA19: =SUM(O19:Z19) -> 187256 | AN19: =SUM(AB19:AM19) -> 0 | AW19: 0 | BA19: =X19-AX19 -> 0 | BB19: =Y19-AY19 -> 0 | BC19: =Z19-AZ19 -> 0
A20: =CONCATENATE(B20,C20,D20,E20,F20,G20,H20,I20,J20,K20,L20,M20,N20) -> СКБСЖРозницаБанкострахованиеНон-лайфСКБЖНСНСРегулярнаяНовый | B20: СКБСЖ | C20: =IFERROR(VLOOKUP(D20,Каналы!$B:$C,2,0),"") -> Розница | D20: Банкострахование | H20: Нон-лайф | I20: СКБЖ | K20: НС | L20: НС | M20: Регулярная | N20: Новый | O20: 2252.64 | P20: 1484.52 | Q20: 551.03 | R20: 384.46 | S20: 374.29 | T20: 396.04 | U20: 290.54 | V20: 281.8 | W20: 283.62 | X20: 300 | Y20: 300 | Z20: 300 | AA20: =SUM(O20:Z20) -> 7198.94 | AN20: =SUM(AB20:AM20) -> 0 | AW20: подняли до уровня 3 кв | BA20: =X20-AX20 -> 300 | BB20: =Y20-AY20 -> 300 | BC20: =Z20-AZ20 -> 300
A21: =CONCATENATE(B21,C21,D21,E21,F21,G21,H21,I21,J21,K21,L21,M21,N21) -> СКБСЖРозницаБанкострахованиеНон-лайфСКБЖНСНСРегулярнаяПролонгация | B21: СКБСЖ | C21: =IFERROR(VLOOKUP(D21,Каналы!$B:$C,2,0),"") -> Розница | D21: Банкострахование | H21: Нон-лайф | I21: СКБЖ | K21: НС | L21: НС | M21: Регулярная | N21: Пролонгация | O21: 4428540 | P21: 4067644.8 | Q21: 4066931.9 | R21: 4266778.6 | S21: 4555055.6 | T21: 3888445.4 | U21: 3958772.4 | V21: 3474961.9 | W21: 3155161.1 | X21: 3000000 | Y21: 3000000 | Z21: 3000000 | AA21: =SUM(O21:Z21) -> 44862292 | AN21: =SUM(AB21:AM21) -> 0 | AW21: ок | AX21: 3000000 | AY21: 3000000 | AZ21: 3000000 | BA21: =X21-AX21 -> 0 | BB21: =Y21-AY21 -> 0 | BC21: =Z21-AZ21 -> 0
A22: =CONCATENATE(B22,C22,D22,E22,F22,G22,H22,I22,J22,K22,L22,M22,N22) -> СКБСЖРозницаWMЛайфНовыйОтдел заботыГКГибкий курсЕдиновременнаяНовый | B22: СКБСЖ | C22: =IFERROR(VLOOKUP(D22,Каналы!$B:$C,2,0),"") -> Розница | D22: WM | H22: Лайф | I22: Новый | J22: Отдел заботы | K22: ГК | L22: Гибкий курс | M22: Единовременная | N22: Новый | P22: 170000 | Q22: 13210990 | R22: 2860000 | S22: 66890000 | T22: 6982000 | U22: 7119907 | V22: 9240000 | W22: 10773123 | X22: 7150000 | Y22: 9250000 | Z22: 10800000 | AA22: =SUM(O22:Z22) -> 1.4444602e+08 | AN22: =SUM(AB22:AM22) -> 0 | AW22: добавлено по факту 3 кв | BA22: =X22-AX22 -> 7150000 | BB22: =Y22-AY22 -> 9250000 | BC22: =Z22-AZ22 -> 10800000
A23: =CONCATENATE(B23,C23,D23,E23,F23,G23,H23,I23,J23,K23,L23,M23,N23) -> СКБСЖРозницаWMЛайфНовыйНСЖ_КБНСЖ с КэшбекомРегулярнаяНовый | B23: СКБСЖ | C23: =IFERROR(VLOOKUP(D23,Каналы!$B:$C,2,0),"") -> Розница | D23: WM | H23: Лайф | I23: Новый | K23: НСЖ_КБ | L23: НСЖ с Кэшбеком | M23: Регулярная | N23: Новый | O23: 3020000 | P23: 6540000 | Q23: 4950000 | R23: 3800000 | S23: 1970000 | T23: 1420000 | U23: 8950000 | V23: 12330000 | W23: 11710000 | X23: 3500000 | Y23: 3500000 | Z23: 3500000 | AA23: =SUM(O23:Z23) -> 65190000 | AN23: =SUM(AB23:AM23) -> 0 | AW23: почему было обнулено окт + нояб? Вернули | AZ23: 3500000 | BA23: =X23-AX23 -> 3500000 | BB23: =Y23-AY23 -> 3500000 | BC23: =Z23-AZ23 -> 0
A24: =CONCATENATE(B24,C24,D24,E24,F24,G24,H24,I24,J24,K24,L24,M24,N24) -> СКБСЖРозницаWMЛайфНовыйНСЖ_КБНСЖ с КэшбекомРегулярнаяПролонгация | B24: СКБСЖ | C24: =IFERROR(VLOOKUP(D24,Каналы!$B:$C,2,0),"") -> Розница | D24: WM | H24: Лайф | I24: Новый | K24: НСЖ_КБ | L24: НСЖ с Кэшбеком | M24: Регулярная | N24: Пролонгация | O24: 1120000 | AA24: =SUM(O24:Z24) -> 1120000 | AN24: =SUM(AB24:AM24) -> 0 | AW24: 0 | BA24: =X24-AX24 -> 0 | BB24: =Y24-AY24 -> 0 | BC24: =Z24-AZ24 -> 0
A25: =CONCATENATE(B25,C25,D25,E25,F25,G25,H25,I25,J25,K25,L25,M25,N25) -> СКБСЖРозницаWMЛайфСКБЖИСЖ_СИВПрочее (СИВ)ЕдиновременнаяНовый | B25: СКБСЖ | C25: =IFERROR(VLOOKUP(D25,Каналы!$B:$C,2,0),"") -> Розница | D25: WM | H25: Лайф | I25: СКБЖ | K25: ИСЖ_СИВ | L25: Прочее (СИВ) | M25: Единовременная | N25: Новый | O25: 0 | P25: 85000000 | Q25: 60000000 | R25: 80000000 | S25: 0 | T25: 0 | U25: 0 | V25: 30000000 | W25: 0 | AA25: =SUM(O25:Z25) -> 255000000 | AN25: =SUM(AB25:AM25) -> 0 | AW25: не ставим прогноз | BA25: =X25-AX25 -> 0 | BB25: =Y25-AY25 -> 0 | BC25: =Z25-AZ25 -> 0
A26: =CONCATENATE(B26,C26,D26,E26,F26,G26,H26,I26,J26,K26,L26,M26,N26) -> СКБСЖРозницаРозница (прочее)ЛайфСКБЖНСЖДело жизниЕдиновременнаяНовый | B26: СКБСЖ | C26: =IFERROR(VLOOKUP(D26,Каналы!$B:$C,2,0),"") -> Розница | D26: Розница (прочее) | H26: Лайф | I26: СКБЖ | K26: НСЖ | L26: Дело жизни | M26: Единовременная | N26: Новый | AA26: =SUM(O26:Z26) -> 0 | AN26: =SUM(AB26:AM26) -> 0 | AW26: обнулен прогноз на этой строке, т.к. заложен выше | BA26: =X26-AX26 -> 0 | BB26: =Y26-AY26 -> 0 | BC26: =Z26-AZ26 -> 0
A27: =CONCATENATE(B27,C27,D27,E27,F27,G27,H27,I27,J27,K27,L27,M27,N27) -> СКБСЖРозницаРозница (прочее)ЛайфСКБЖНСЖПрочее (СКБЖ)РегулярнаяНовый | B27: СКБСЖ | C27: =IFERROR(VLOOKUP(D27,Каналы!$B:$C,2,0),"") -> Розница | D27: Розница (прочее) | H27: Лайф | I27: СКБЖ | K27: НСЖ | L27: Прочее (СКБЖ) | M27: Регулярная | N27: Новый | AA27: =SUM(O27:Z27) -> 0 | AN27: =SUM(AB27:AM27) -> 0 | AW27: обнулено, нет факта | BA27: =X27-AX27 -> 0 | BB27: =Y27-AY27 -> 0 | BC27: =Z27-AZ27 -> 0
A28: =CONCATENATE(B28,C28,D28,E28,F28,G28,H28,I28,J28,K28,L28,M28,N28) -> СКБСЖРозницаРозница (прочее)ЛайфСКБЖНСЖПрочее (СКБЖ)РегулярнаяПролонгация | B28: СКБСЖ | C28: =IFERROR(VLOOKUP(D28,Каналы!$B:$C,2,0),"") -> Розница | D28: Розница (прочее) | H28: Лайф | I28: СКБЖ | K28: НСЖ | L28: Прочее (СКБЖ) | M28: Регулярная | N28: Пролонгация | AA28: =SUM(O28:Z28) -> 0 | AN28: =SUM(AB28:AM28) -> 0 | AW28: обнулено, нет факта | BA28: =X28-AX28 -> 0 | BB28: =Y28-AY28 -> 0 | BC28: =Z28-AZ28 -> 0
A29: =CONCATENATE(B29,C29,D29,E29,F29,G29,H29,I29,J29,K29,L29,M29,N29) -> СКБСЖРозницаWMЛайфСКБЖНСЖ_СИВCiti ComfortРегулярнаяПролонгация | B29: СКБСЖ | C29: =IFERROR(VLOOKUP(D29,Каналы!$B:$C,2,0),"") -> Розница | D29: WM | H29: Лайф | I29: СКБЖ | K29: НСЖ_СИВ | L29: Citi Comfort | M29: Регулярная | N29: Пролонгация | O29: 18410377 | P29: 21487153 | Q29: 47554502 | R29: 19857180 | S29: 38031110 | T29: 29276082 | U29: 36137478 | V29: 28538487 | W29: 18640075 | X29: 36500000 | Y29: 29000000 | Z29: 19000000 | AA29: =SUM(O29:Z29) -> 3.4243244e+08 | AB29: =O29*0.5 -> 9205188.3 | AC29: =P29*0.5 -> 10743576 | AD29: =Q29*0.5 -> 23777251 | AE29: =R29*0.5 -> 9928590.2 | AF29: =S29*0.5 -> 19015555 | AG29: =T29*0.5 -> 14638041 | AH29: =U29*0.5 -> 18068739 | AI29: =V29*0.5 -> 14269244 | ... AM29: =Z29*0.5 -> 9500000 | AN29: =SUM(AB29:AM29) -> 1.7121622e+08 | AW29: подняли до уровня 3 кв | BA29: =X29-AX29 -> 36500000 | BB29: =Y29-AY29 -> 29000000 | BC29: =Z29-AZ29 -> 19000000
A30: =CONCATENATE(B30,C30,D30,E30,F30,G30,H30,I30,J30,K30,L30,M30,N30) -> СКБСЖРозницаWMЛайфСКБЖНСЖ_СИВCiti HealthЕдиновременнаяНовый | B30: СКБСЖ | C30: =IFERROR(VLOOKUP(D30,Каналы!$B:$C,2,0),"") -> Розница | D30: WM | H30: Лайф | I30: СКБЖ | K30: НСЖ_СИВ | L30: Citi Health | M30: Единовременная | N30: Новый | O30: 0 | W30: 0 | AA30: =SUM(O30:Z30) -> 0 | AN30: =SUM(AB30:AM30) -> 0 | AW30: 0 | BA30: =X30-AX30 -> 0 | BB30: =Y30-AY30 -> 0 | BC30: =Z30-AZ30 -> 0
A31: =CONCATENATE(B31,C31,D31,E31,F31,G31,H31,I31,J31,K31,L31,M31,N31) -> СКБСЖРозницаWMЛайфСКБЖНСЖ_СИВCiti HealthРегулярнаяПролонгация | B31: СКБСЖ | C31: =IFERROR(VLOOKUP(D31,Каналы!$B:$C,2,0),"") -> Розница | D31: WM | H31: Лайф | I31: СКБЖ | K31: НСЖ_СИВ | L31: Citi Health | M31: Регулярная | N31: Пролонгация | O31: 20658385 | P31: 30591993 | Q31: 23807663 | R31: 57329914 | S31: 32240018 | T31: 43752002 | U31: 30135269 | V31: 18398511 | W31: 18218176 | X31: 31200000 | Y31: 18500000 | Z31: 18500000 | AA31: =SUM(O31:Z31) -> 3.4333193e+08 | AB31: =O31*0.5 -> 10329193 | AC31: =P31*0.5 -> 15295996 | AD31: =Q31*0.5 -> 11903832 | AE31: =R31*0.5 -> 28664957 | AF31: =S31*0.5 -> 16120009 | AG31: =T31*0.5 -> 21876001 | AH31: =U31*0.5 -> 15067634 | AI31: =V31*0.5 -> 9199255.3 | ... AM31: =Z31*0.5 -> 9250000 | AN31: =SUM(AB31:AM31) -> 1.7166597e+08 | AW31: подняли до уровня 3 кв | BA31: =X31-AX31 -> 31200000 | BB31: =Y31-AY31 -> 18500000 | BC31: =Z31-AZ31 -> 18500000
A32: =CONCATENATE(B32,C32,D32,E32,F32,G32,H32,I32,J32,K32,L32,M32,N32) -> СКБСЖРозницаWMЛайфСКБЖНСЖ_СИВCiti KidsЕдиновременнаяНовый | B32: СКБСЖ | C32: =IFERROR(VLOOKUP(D32,Каналы!$B:$C,2,0),"") -> Розница | D32: WM | H32: Лайф | I32: СКБЖ | K32: НСЖ_СИВ | L32: Citi Kids | M32: Единовременная | N32: Новый | O32: 0 | P32: 0 | Q32: 0 | R32: 0 | S32: 0 | T32: 0 | U32: 0 | V32: 0 | W32: 0 | AA32: =SUM(O32:Z32) -> 0 | AN32: =SUM(AB32:AM32) -> 0 | AW32: 0 | BA32: =X32-AX32 -> 0 | BB32: =Y32-AY32 -> 0 | BC32: =Z32-AZ32 -> 0
A33: =CONCATENATE(B33,C33,D33,E33,F33,G33,H33,I33,J33,K33,L33,M33,N33) -> СКБСЖРозницаWMЛайфСКБЖНСЖ_СИВCiti KidsРегулярнаяПролонгация | B33: СКБСЖ | C33: =IFERROR(VLOOKUP(D33,Каналы!$B:$C,2,0),"") -> Розница | D33: WM | H33: Лайф | I33: СКБЖ | K33: НСЖ_СИВ | L33: Citi Kids | M33: Регулярная | N33: Пролонгация | O33: 5831098 | P33: 6117249.5 | Q33: 7756441.3 | R33: 4418466.3 | S33: 5748158.3 | T33: 9817342.2 | U33: 3900115.4 | V33: 6670744.4 | W33: 10019313 | X33: 400000 | Y33: 6700000 | Z33: 10000000 | AA33: =SUM(O33:Z33) -> 77378929 | AB33: =O33*0.5 -> 2915549 | AC33: =P33*0.5 -> 3058624.7 | AD33: =Q33*0.5 -> 3878220.6 | AE33: =R33*0.5 -> 2209233.1 | AF33: =S33*0.5 -> 2874079.2 | AG33: =T33*0.5 -> 4908671.1 | AH33: =U33*0.5 -> 1950057.7 | AI33: =V33*0.5 -> 3335372.2 | ... AM33: =Z33*0.5 -> 5000000 | AN33: =SUM(AB33:AM33) -> 38689464 | AW33: подняли до уровня 3 кв | BA33: =X33-AX33 -> 400000 | BB33: =Y33-AY33 -> 6700000 | BC33: =Z33-AZ33 -> 10000000
A34: =CONCATENATE(B34,C34,D34,E34,F34,G34,H34,I34,J34,K34,L34,M34,N34) -> СКБСЖРозницаWMЛайфСКБЖНСЖ_СИВCiti PremiumЕдиновременнаяНовый | B34: СКБСЖ | C34: =IFERROR(VLOOKUP(D34,Каналы!$B:$C,2,0),"") -> Розница | D34: WM | H34: Лайф | I34: СКБЖ | K34: НСЖ_СИВ | L34: Citi Premium | M34: Единовременная | N34: Новый | P34: 0 | V34: 0 | AA34: =SUM(O34:Z34) -> 0 | AN34: =SUM(AB34:AM34) -> 0 | AW34: 0 | BA34: =X34-AX34 -> 0 | BB34: =Y34-AY34 -> 0 | BC34: =Z34-AZ34 -> 0
A35: =CONCATENATE(B35,C35,D35,E35,F35,G35,H35,I35,J35,K35,L35,M35,N35) -> СКБСЖРозницаWMЛайфСКБЖНСЖ_СИВCiti PremiumРегулярнаяПролонгация | B35: СКБСЖ | C35: =IFERROR(VLOOKUP(D35,Каналы!$B:$C,2,0),"") -> Розница | D35: WM | H35: Лайф | I35: СКБЖ | K35: НСЖ_СИВ | L35: Citi Premium | M35: Регулярная | N35: Пролонгация | O35: 13187633 | P35: 12480846 | Q35: 7726525.5 | R35: 19139304 | S35: 15472515 | T35: 18532815 | U35: 14041567 | V35: 11396480 | W35: 15022084 | X35: 14000000 | Y35: 11400000 | Z35: 15000000 | AA35: =SUM(O35:Z35) -> 1.6739977e+08 | AB35: =O35*0.5 -> 6593816.4 | AC35: =P35*0.5 -> 6240423.2 | AD35: =Q35*0.5 -> 3863262.8 | AE35: =R35*0.5 -> 9569651.9 | AF35: =S35*0.5 -> 7736257.5 | AG35: =T35*0.5 -> 9266407.7 | AH35: =U35*0.5 -> 7020783.3 | AI35: =V35*0.5 -> 5698239.9 | ... AM35: =Z35*0.5 -> 7500000 | AN35: =SUM(AB35:AM35) -> 83699885 | AW35: подняли до уровня 3 кв | BA35: =X35-AX35 -> 14000000 | BB35: =Y35-AY35 -> 11400000 | BC35: =Z35-AZ35 -> 15000000
A36: =CONCATENATE(B36,C36,D36,E36,F36,G36,H36,I36,J36,K36,L36,M36,N36) -> СКБСЖРозницаWMЛайфСКБЖНСЖ_СИВПрочее (СИВ)ЕдиновременнаяНовый | B36: СКБСЖ | C36: =IFERROR(VLOOKUP(D36,Каналы!$B:$C,2,0),"") -> Розница | D36: WM | H36: Лайф | I36: СКБЖ | K36: НСЖ_СИВ | L36: Прочее (СИВ) | M36: Единовременная | N36: Новый | P36: 0 | AA36: =SUM(O36:Z36) -> 0 | AN36: =SUM(AB36:AM36) -> 0 | AW36: 0 | BA36: =X36-AX36 -> 0 | BB36: =Y36-AY36 -> 0 | BC36: =Z36-AZ36 -> 0
A37: =CONCATENATE(B37,C37,D37,E37,F37,G37,H37,I37,J37,K37,L37,M37,N37) -> СКБСЖРозницаWMЛайфСКБЖНСЖ_СИВПрочее (СИВ)РегулярнаяПролонгация | B37: СКБСЖ | C37: =IFERROR(VLOOKUP(D37,Каналы!$B:$C,2,0),"") -> Розница | D37: WM | H37: Лайф | I37: СКБЖ | K37: НСЖ_СИВ | L37: Прочее (СИВ) | M37: Регулярная | N37: Пролонгация | O37: 503886.87 | P37: 5027505.5 | Q37: 1765599.7 | R37: 4102683.1 | S37: 1189403.2 | T37: 1983821.4 | U37: 1014276.9 | V37: 1549964.6 | W37: 2316840.2 | X37: 1000000 | Y37: 1500000 | Z37: 2350000 | AA37: =SUM(O37:Z37) -> 24303982 | AB37: =O37*0.5 -> 251943.44 | AC37: =P37*0.5 -> 2513752.8 | AD37: =Q37*0.5 -> 882799.84 | AE37: =R37*0.5 -> 2051341.6 | AF37: =S37*0.5 -> 594701.6 | AG37: =T37*0.5 -> 991910.69 | AH37: =U37*0.5 -> 507138.43 | AI37: =V37*0.5 -> 774982.32 | ... AM37: =Z37*0.5 -> 1175000 | AN37: =SUM(AB37:AM37) -> 12151991 | AW37: подняли до уровня 3 кв | BA37: =X37-AX37 -> 1000000 | BB37: =Y37-AY37 -> 1500000 | BC37: =Z37-AZ37 -> 2350000
A38: =CONCATENATE(B38,C38,D38,E38,F38,G38,H38,I38,J38,K38,L38,M38,N38) -> СКБСЖРозницаWMЛайфСКБЖНСЖ_СИВСтабильный курсЕдиновременнаяНовый | B38: СКБСЖ | C38: =IFERROR(VLOOKUP(D38,Каналы!$B:$C,2,0),"") -> Розница | D38: WM | H38: Лайф | I38: СКБЖ | K38: НСЖ_СИВ | L38: Стабильный курс | M38: Единовременная | N38: Новый | O38: 26751017 | P38: 54354258 | Q38: 94008406 | R38: 1.0344756e+08 | S38: 74110009 | T38: 1.3434973e+08 | U38: 65855565 | V38: 1.1670813e+08 | W38: 19812750 | X38: 67000000 | Y38: 67000000 | Z38: 67000000 | AA38: =SUM(O38:Z38) -> 8.9039742e+08 | AB38: 20000000 | AC38: 25000000 | AD38: 40000000 | AE38: 50000000 | AF38: 30000000 | AG38: 50000000 | AH38: 50000000 | AI38: 50000000 | AJ38: 70000000 | AK38: 70000000 | AL38: 70000000 | AM38: 70000000 | AN38: =SUM(AB38:AM38) -> 595000000 | AW38: подняли до уровня 3 кв | AX38: 56000000 | AY38: 25000000 | AZ38: 25000000 | BA38: =X38-AX38 -> 11000000 | BB38: =Y38-AY38 -> 42000000 | BC38: =Z38-AZ38 -> 42000000
A39: =CONCATENATE(B39,C39,D39,E39,F39,G39,H39,I39,J39,K39,L39,M39,N39) -> СКБСЖРозницаWMЛайфСКБЖНСЖ_СИВСтабильный курсРегулярнаяНовый | B39: СКБСЖ | C39: =IFERROR(VLOOKUP(D39,Каналы!$B:$C,2,0),"") -> Розница | D39: WM | H39: Лайф | I39: СКБЖ | K39: НСЖ_СИВ | L39: Стабильный курс | M39: Регулярная | N39: Новый | O39: 431915.26 | P39: 1969383.9 | R39: 665749.29 | S39: 486687.65 | T39: 175422.25 | U39: 407935.73 | V39: 49748.26 | AA39: =SUM(O39:Z39) -> 4186842.4 | AN39: =SUM(AB39:AM39) -> 0 | AW39: 0 | BA39: =X39-AX39 -> 0 | BB39: =Y39-AY39 -> 0 | BC39: =Z39-AZ39 -> 0
A40: =CONCATENATE(B40,C40,D40,E40,F40,G40,H40,I40,J40,K40,L40,M40,N40) -> СКБСЖРозницаWMЛайфСКБЖНСЖ_СИВСтабильный курсРегулярнаяПролонгация | B40: СКБСЖ | C40: =IFERROR(VLOOKUP(D40,Каналы!$B:$C,2,0),"") -> Розница | D40: WM | H40: Лайф | I40: СКБЖ | K40: НСЖ_СИВ | L40: Стабильный курс | M40: Регулярная | N40: Пролонгация | P40: 1636296.9 | Q40: 1276658.3 | R40: 710630.34 | S40: 1989930.2 | T40: 1801710.7 | U40: 2818490 | V40: 3919556.7 | W40: 3441442.8 | X40: 79714940 | Y40: 73347001 | Z40: 1.6705824e+08 | AA40: =SUM(O40:Z40) -> 3.377149e+08 | AB40: =O40*0.5 -> 0 | AC40: =P40*0.5 -> 818148.47 | AD40: =Q40*0.5 -> 638329.17 | AE40: =R40*0.5 -> 355315.17 | AF40: =S40*0.5 -> 994965.12 | AG40: =T40*0.5 -> 900855.35 | AH40: =U40*0.5 -> 1409245 | AI40: =V40*0.5 -> 1959778.4 | ... AM40: =Z40*0.5 -> 83529119 | AN40: =SUM(AB40:AM40) -> 1.6885745e+08 | AW40: ок | AX40: 79714940 | AY40: 73347001 | AZ40: 1.6705824e+08 | BA40: =X40-AX40 -> 0 | BB40: =Y40-AY40 -> 0 | BC40: =Z40-AZ40 -> 0
...

Sheet Свод
A2: Компания | B2: (Все)
A3: L/NL | B3: (Все)
A4: Канал | B4: (Все)
A5: Подканал (код) | B5: (Все)
A6: Регион | B6: (Все)
A7: Новые ТП | B7: (Все)
A8: Периодичность | B8: (Все)
A10: Названия строк | B10: янв.25 | C10: фев.25 | D10: мар.25 | E10: апр.25 | F10: май.25 | G10: июн.25 | H10: июл.25 | I10: авг.25 | J10: сен.25 | K10: окт.25 | L10: ноя.25 | M10: дек.25 | N10: 2025г | O10: янв.26 | P10: фев.26 | Q10: мар.26 | R10: апр.26 | S10: июн.26 | T10: июл.26 | U10: авг.26 | V10: сен.26 | W10: окт.26 | X10: ноя.26 | Y10: дек.26 | Z10: 2026г | AA10: 2026/2025,% | AB10: 2027 | AC10: 2028
A11: Новый | B11: 2.885444e+09 | C11: 4162027677 | D11: 6.6129975e+09 | E11: 1.4393284e+09 | F11: 2.2170324e+09 | G11: 2.2433754e+09 | H11: 2492508689 | I11: 531752537 | J11: 8.660797e+08 | K11: 668500000 | L11: 575500000 | M11: 579000000 | N11: 2.5273546e+10 | Z11: 0 | AA11: 0
A12: ГК | B12: 2.6573514e+08 | C12: 208476422 | D12: 2.2908286e+08 | E12: 411551916 | F12: 250003109 | G12: 2.7807913e+08 | H12: 280055521 | I12: 1.9486686e+08 | J12: 2.7312459e+08 | K12: 270000000 | L12: 220000000 | M12: 220000000 | N12: 3.1009755e+09 | Z12: 0 | AA12: 0
A13: НСЖ_КБ | B13: -10040000 | C13: 12340000 | D13: 13850000 | E13: 1670000 | F13: 5850000 | G13: 10980000 | H13: 21630000 | I13: 8450000 | J13: 9560000 | K13: 5500000 | L13: 5500000 | M13: 9000000 | N13: 94290000 | Z13: 0 | AA13: 0
A14: НП | B14: 2.6297489e+09 | C14: 3941211255 | D14: 6.3700647e+09 | E14: 1.0261065e+09 | F14: 1.9611793e+09 | G14: 1954316259 | H14: 2190823168 | I14: 328435677 | J14: 583395118 | K14: 393000000 | L14: 350000000 | M14: 350000000 | N14: 2.2078281e+10 | Z14: 0 | AA14: 0
A15: СКБЖ | B15: 4.4174977e+08 | C15: 5.7662942e+08 | D15: 6.9973975e+08 | E15: 7.9196842e+08 | F15: 5.73171e+08 | G15: 5.2868715e+08 | H15: 4.1378283e+08 | I15: 6.4790666e+08 | J15: 5.2165516e+08 | K15: 9.4047484e+08 | L15: 6.482189e+08 | M15: 7.1781814e+08 | N15: 7.501802e+09 | Z15: 0 | AA15: 0
A16: ДМС | L16: 24112000 | N16: 24112000 | Z16: 0 | AA16: 0
A17: НС | B17: 4479046.6 | C17: 4127138.3 | D17: 4134853.9 | E17: 5554023.1 | F17: 5644432.9 | G17: 4588408.4 | H17: 4633227 | I17: 4601561.7 | J17: 4227523.7 | K17: 3000000 | L17: 3000000 | M17: 3000000 | N17: 50990216 | Z17: 0 | AA17: 0
A18: Индив.пенсия | H18: 373954.08 | I18: -0.01 | N18: 373954.07 | Z18: 0 | AA18: 0
A19: НСЖ | B19: 3.402138e+08 | C19: 3.4144043e+08 | D19: 4.3791931e+08 | E19: 4.7882016e+08 | F19: 3.8189401e+08 | G19: 2.6874964e+08 | H19: 2.4263785e+08 | I19: 3.7692148e+08 | J19: 3.569011e+08 | K19: 170250000 | L19: 170250000 | M19: 170250000 | N19: 3.7362478e+09 | Z19: 0 | AA19: 0
A20: НСЖ_СИВ | B20: 85774312 | C20: 1.3366469e+08 | D20: 1.838958e+08 | E20: 2.0967148e+08 | F20: 1.6926783e+08 | G20: 2.3968892e+08 | H20: 1.543107e+08 | I20: 2.2398183e+08 | J20: 1.5109356e+08 | K20: 7.6471494e+08 | L20: 4.48347e+08 | M20: 5.4205824e+08 | N20: 3.3064693e+09 | Z20: 0 | AA20: 0
A21: НСЖ_СИВ_ДМС | B21: 1885052.5 | C21: 3749114.3 | D21: 3451018.1 | E21: 7409143.2 | F21: 3730224.5 | G21: 5077303.3 | H21: 3260473.2 | I21: 2542562.4 | J21: 1843966.6 | N21: 32948858 | Z21: 0 | AA21: 0
A22: НСЖ_СИВ_НС | B22: 1629991.7 | C22: 2077277.6 | D22: 2577605.3 | E22: 2113243.7 | F22: 2840493.8 | G22: 2750863.2 | H22: 2997070.2 | I22: 2860870.8 | J22: 2393164.9 | N22: 22240581 | Z22: 0 | AA22: 0
A23: ИСЖ_СИВ | B23: 0 | C23: 85000000 | D23: 60000000 | E23: 80000000 | F23: 0 | G23: 0 | H23: 0 | I23: 30000000 | J23: 0 | N23: 255000000 | Z23: 0 | AA23: 0
A24: ДМС_СИВ | B24: 86937.21 | C24: 0 | D24: 52231.56 | E24: 19451.63 | F24: 48014.15 | G24: 112944.58 | H24: 0 | I24: 38708.2 | J24: -2700.99 | N24: 355586.34 | Z24: 0 | AA24: 0
A25: КСЖ | B25: 7023512.7 | C25: 6057238.2 | D25: 7153090 | E25: 8713385.6 | F25: 9625379.3 | G25: 7747570.3 | H25: 5232509.6 | I25: 6813129.9 | J25: 5080830.4 | K25: 2509900 | L25: 2509900 | M25: 2509900 | N25: 70976346 | Z25: 0 | AA25: 0
A26: КСЖ_СИВ | B26: 462576.4 | C26: 413099.12 | D26: 402065.43 | E26: -430844.41 | F26: -9312.31 | G26: 0 | N26: 837584.23 | Z26: 0 | AA26: 0
A27: НС_СИВ | B27: 194550 | C27: 100440 | D27: 153780 | E27: 98370 | F27: 129930 | G27: -28500 | H27: 337050 | I27: 146520 | J27: 117720 | N27: 1249860 | Z27: 0 | AA27: 0
A28: Уралсиб | B28: 2.7209081e+08 | C28: 1.9753412e+08 | D28: 1.5835023e+08 | E28: 3.0697269e+08 | F28: 2.5583722e+08 | G28: 3.3139591e+08 | H28: 5.1287018e+08 | I28: 4.1217618e+08 | J28: 3.51064e+08 | K28: 1.3984747e+08 | L28: 1.5451164e+08 | M28: 1.5470505e+08 | N28: 3.2473555e+09 | Z28: 0 | AA28: 0
A29: ИСЖ_Уралсиб | B29: 45539490 | C29: 50830397 | D29: 30800558 | E29: 44427530 | F29: 32141234 | G29: 30905468 | H29: 11352350 | I29: -5019691 | J29: 1500000 | K29: 3500000 | L29: 18000000 | M29: 18000000 | N29: 2.8197734e+08 | Z29: 0 | AA29: 0
A30: НСЖ_Уралсиб | B30: 1.939983e+08 | C30: 1.0045759e+08 | D30: 83488475 | E30: 2.2768608e+08 | F30: 1.8297711e+08 | G30: 2.5687819e+08 | H30: 4.6571009e+08 | I30: 3.6600019e+08 | J30: 3.0787438e+08 | K30: 140000000 | L30: 140000000 | M30: 140000000 | N30: 2.6050704e+09 | Z30: 0 | AA30: 0
A31: КСЖ_Уралсиб | B31: 32547109 | C31: 46227427 | D31: 44040140 | E31: 34850041 | F31: 40723875 | G31: 43604231 | H31: 35799994 | I31: 51187726 | J31: 41682075 | K31: -3652532.7 | L31: -3488361.4 | M31: -3294950.5 | N31: 3.6022677e+08 | Z31: 0 | AA31: 0
A32: Прочее_Уралсиб | B32: 5914 | C32: 18703.26 | D32: 21062 | E32: 9033 | F32: -4998 | G32: 8023 | H32: 7745.66 | I32: 7951.42 | J32: 7546.99 | N32: 80981.33 | Z32: 0 | AA32: 0
A33: (пусто) | N33: 0 | Z33: 0 | AA33: #VALUE!
A34: Общий итог | B34: 3.5992846e+09 | C34: 4.9361912e+09 | D34: 7.4710875e+09 | E34: 2.5382695e+09 | F34: 3.0460406e+09 | G34: 3.1034584e+09 | H34: 3.4191617e+09 | I34: 1.5918354e+09 | J34: 1.7387989e+09 | K34: 1.7488223e+09 | L34: 1.3782305e+09 | M34: 1.4515232e+09 | N34: 3.6022704e+10 | Z34: 0 | AA34: 0

Sheet Каналы
B2: СПРАВОЧНИК КАНАЛОВ ПРОДАЖ
B3: Подканал | C3: Канал | D3: Код канала (продукта) | F3: Подканал | G3: Компания | I3: Розница | J3: Уралсиб_ | K3: Агенты | L3: Корпораты | M3: Мульти
B4: Агенты | C4: Агенты | F4: WM | G4: СКБС | I4: WM | J4: Уралсиб | K4: Агенты | L4: Корпораты | M4: Мульти
B5: Брокеры | C5: Агенты | F5: Банкострахование | G5: СКБСЖ | I5: Банкострахование | K5: Брокеры
B6: Корпораты | C6: Корпораты | F6: Розница (прочее) | I6: Розница (прочее)
B7: Мульти | C7: Мульти | F7: Рыночный НС | I7: Рыночный НС
B8: WM | C8: Розница | F8: Уралсиб
B9: Банкострахование | C9: Розница | F9: Агенты
B10: Розница (прочее) | C10: Розница | F10: Брокеры
B11: Рыночный НС | C11: Розница | F11: Корпораты
B12: Уралсиб | C12: Уралсиб_ | F12: Мульти

Sheet Регионы
B1: СПРАВОЧНИК РЕГИОНОВ | F1: СПРАВОЧНИК НОВЫХ ТОЧЕК ПРОДАЖ | I1: !!! Для Добавления Новых Точек продаж в форму Вам необходимо: 1) в столбце "Регион" выбрать из выпадающего списка Регион; 2) далее в столбце "Новые ТП" вести вручную название новой ТП (каждую точку на отдельной строке), по которому будем ее идентифицировать в бюджете. NB! Название должно быть таким же, которое Вы используете в форме "по Бюджету Расходов по этой новой точке.
B2: Регион | C2: признак | F2: Регион | G2: Новые ТП | H2: признак | I2: пояснение к добавлению новой точки
B3: Адыгея | C3: текущие точки | F3: Якутия | G3: Новая ТП_.11 | H3: новые точки
B4: Алтай | C4: текущие точки | H4: новые точки
B5: Анадырь | C5: текущие точки | H5: новые точки
B6: Архангельск | C6: текущие точки | H6: новые точки
B7: Астрахань | C7: текущие точки | H7: новые точки
B8: Барнаул | C8: текущие точки | H8: новые точки
B9: Башкортостан | C9: текущие точки | H9: новые точки
B10: Белгород | C10: текущие точки | H10: новые точки
B11: Биробиджан | C11: текущие точки | H11: новые точки
B12: Благовещенск | C12: текущие точки | H12: новые точки
B13: Брянск | C13: текущие точки | H13: новые точки
B14: Бурятия | C14: текущие точки | H14: новые точки
B15: Великий Новгород | C15: текущие точки | H15: новые точки
... B18: Волгоград | C18: текущие точки | H18: новые точки
B19: Вологда | C19: текущие точки
B20: Воронеж | C20: текущие точки
B21: Дагестан | C21: текущие точки
B22: Донецк | C22: текущие точки
B23: Екатеринбург | C23: текущие точки
B24: Иваново | C24: текущие точки
B25: Ингушетия | C25: текущие точки
B26: Иркутск | C26: текущие точки
B27: Кабардино-Балкария | C27: текущие точки
B28: Калининград | C28: текущие точки
B29: Калмыкия | C29: текущие точки
B30: Калуга | C30: текущие точки
... B91: Новый регион | C91: текущие точки

Sheet спр
A1: старое наименование | B1: новое наименование
A2: Линия бизнеса | B2: Линия бизнеса (форма)
A3: Гибкий курс | B3: ГК
A4: НП | B4: НП
A5: НСЖ | B5: НСЖ
A6: НСЖ с Кэшбеком | B6: НСЖ_КБ
A7: Групп. пенсия | B7: Групп.пенсия
A8: Индив. пенсия | B8: Индив.пенсия
A9: ИСЖ (СиВ) | B9: ИСЖ_СИВ
A10: НСЖ (СиВ) | B10: НСЖ_СИВ
A11: ИСЖ (Уралсиб) | B11: ИСЖ_Уралсиб
A12: НСЖ (Уралсиб) | B12: НСЖ_Уралсиб
... A24: Прочее (Уралсиб) | B24: Прочее_Уралсиб

Sheet ЛБ
E1: 1. Выбираем Портфель (вып список) - > 2. выбираем Линию бизнеса (вып.список) - 3. Выбираем продукт (вып список)
B2: Справочник продуктов | J2: Портфели - ЛБ (для выбора в форме) | P2: Доп аналитики (для выбора в форме
B3: Продукт | C3: Линия бизнеса (форма) | D3: Портфель | E3: L/NL | H3: Портфель | J3: Новый | K3: СКБСЖ | L3: Уралсиб | P3: Новый бизнес/ Пролонгация | R3: Периодичность
B4: Гибкий курс | C4: ГК | D4: Новый | E4: Лайф | H4: Новый | J4: ГК | K4: Групп.пенсия | L4: ИСЖ_Уралсиб | P4: Пролонгация | R4: Единовременная
B5: НП | C5: НП | D5: Новый | E5: Лайф | H5: СКБСЖ | J5: НП | K5: Индив.пенсия | L5: НСЖ_Уралсиб | P5: Новый | R5: Регулярная
B6: Будущее под ключ | C6: НСЖ_новый | D6: Новый | E6: Лайф | H6: Уралсиб | J6: НСЖ_новый | K6: НСЖ | L6: КСЖ_Уралсиб
B7: НСЖ с Кэшбеком | C7: НСЖ_КБ | D7: Новый | E7: Лайф | J7: НСЖ_КБ | K7: НСЖ_СИВ | L7: Прочее_Уралсиб
B8: Групп. пенсия | C8: Групп.пенсия | D8: СКБСЖ | E8: Лайф | K8: ИСЖ_СИВ
B9: Индив Пенсия | C9: Индив.пенсия | D9: СКБСЖ | E9: Лайф | K9: ДМС
B10: Прочее (СИВ) | C10: ИСЖ_СИВ | D10: СКБСЖ | E10: Лайф | K10: ДМС_СИВ
B11: Дело жизни | C11: НСЖ | D11: СКБСЖ | E11: Лайф | K11: КорпЖ
B12: Детский капитал | C12: НСЖ | D12: СКБСЖ | E12: Лайф | K12: КорпНС
B13: Классика+ | C13: НСЖ | D13: СКБСЖ | E13: Лайф | K13: КСЖ
B14: Курс жизни Про | C14: НСЖ | D14: СКБСЖ | E14: Лайф | K14: КСЖ_СИВ
B15: Максимальная выгода | C15: НСЖ | D15: СКБСЖ | E15: Лайф | K15: НС
B16: Прочее (СКБЖ) | C16: НСЖ | D16: СКБСЖ | E16: Лайф | K16: НС_СИВ
B17: Юниор+ | C17: НСЖ | D17: СКБСЖ | E17: Лайф | K17: НСЖ_СИВ_ДМС
B18: Citi Comfort | C18: НСЖ_СИВ | D18: СКБСЖ | E18: Лайф | K18: НСЖ_СИВ_НС
B19: Citi Health | C19: НСЖ_СИВ | D19: СКБСЖ | E19: Лайф
B20: Citi Kids | C20: НСЖ_СИВ | D20: СКБСЖ | E20: Лайф | I20: ЛБ - Продукт для выбора в форме
B21: Citi Premium | C21: НСЖ_СИВ | D21: СКБСЖ | E21: Лайф | I21: ГК | J21: НП | K21: НСЖ_новый | L21: НСЖ_КБ | M21: Групп.пенсия | N21: Индив.пенсия | O21: НСЖ | P21: НСЖ_СИВ | Q21: ИСЖ_СИВ | R21: ДМС | S21: ДМС_СИВ | T21: КорпЖ | U21: КорпНС | V21: КСЖ | W21: КСЖ_СИВ | X21: НС | Y21: НС_СИВ | Z21: НСЖ_СИВ_ДМС | AA21: НСЖ_СИВ_НС | AB21: ИСЖ_Уралсиб | AC21: НСЖ_Уралсиб | AD21: КСЖ_Уралсиб | AE21: Прочее_Уралсиб
B22: Прочее (СИВ) | C22: НСЖ_СИВ | D22: СКБСЖ | E22: Лайф | I22: Гибкий курс | J22: НП | K22: Будущее под ключ | L22: НСЖ с Кэшбеком | M22: Групп. пенсия | N22: Индив Пенсия | O22: Дело жизни | P22: Citi Comfort | Q22: Прочее (СИВ) | R22: ДМС | S22: Прочее (СИВ) | T22: КорпЖ | U22: КорпНС | V22: КСЖ | W22: Прочее (СИВ) | X22: Дело жизни | Y22: Прочее (СИВ) | Z22: Citi Comfort | AA22: Citi Comfort | AB22: Верное решение | AC22: Легкий старт | AD22: КСЖ (Уралсиб) | AE22: Прочее (Уралсиб)
B23: Сила процента | C23: НСЖ_СИВ | D23: СКБСЖ | E23: Лайф | O23: Детский капитал | P23: Citi Health | X23: НС | Z23: Citi Health | AA23: Citi Health | AC23: Прочее (Уралсиб) | AD23: Прочее (Уралсиб)
B24: Стабильный курс | C24: НСЖ_СИВ | D24: СКБСЖ | E24: Лайф | O24: Классика+ | P24: Citi Kids | Z24: Citi Kids | AA24: Citi Kids | AC24: Стабильный доход
B25: Верное решение | C25: ИСЖ_Уралсиб | D25: Уралсиб | E25: Лайф | O25: Курс жизни Про | P25: Citi Premium | Z25: Citi Premium | AA25: Citi Premium
B26: Легкий старт | C26: НСЖ_Уралсиб | D26: Уралсиб | E26: Лайф | O26: Максимальная выгода | P26: Прочее (СИВ) | Z26: Прочее (СИВ) | AA26: Прочее (СИВ)
B27: Прочее (Уралсиб) | C27: НСЖ_Уралсиб | D27: Уралсиб | E27: Лайф | O27: Прочее (СКБЖ) | P27: Сила процента | Z27: Сила процента | AA27: Сила процента
B28: Стабильный доход | C28: НСЖ_Уралсиб | D28: Уралсиб | E28: Лайф | O28: Юниор+ | P28: Стабильный курс | Z28: Стабильный курс | AA28: Стабильный курс
B29: ДМС | C29: ДМС | D29: СКБСЖ | E29: Нон-лайф
B30: Прочее (СИВ) | C30: ДМС_СИВ | D30: СКБСЖ | E30: Нон-лайф
B31: КорпЖ | C31: КорпЖ | D31: СКБСЖ | E31: Нон-лайф
B32: КорпНС | C32: КорпНС | D32: СКБСЖ | E32: Нон-лайф
B33: КСЖ | C33: КСЖ | D33: СКБСЖ | E33: Нон-лайф
B34: Прочее (СИВ) | C34: КСЖ_СИВ | D34: СКБСЖ | E34: Нон-лайф
B35: Дело жизни | C35: НС | D35: СКБСЖ | E35: Нон-лайф
B36: НС | C36: НС | D36: СКБСЖ | E36: Нон-лайф
B37: Прочее (СИВ) | C37: НС_СИВ | D37: СКБСЖ | E37: Нон-лайф
B38: Citi Comfort | C38: НСЖ_СИВ_ДМС | D38: СКБСЖ | E38: Нон-лайф
B39: Citi Health | C39: НСЖ_СИВ_ДМС | D39: СКБСЖ | E39: Нон-лайф
B40: Citi Kids | C40: НСЖ_СИВ_ДМС | D40: СКБСЖ | E40: Нон-лайф
...
